Workbook

Sheet Guide
A1: OpenPath: educator review of the consonant-doubling journey
A3: What this is
A4: Every question, lesson, hint, practice word, draft threshold and parent-facing sentence in the doubling journey, exactly as the app shows them. Nothing here has been reviewed by an educator yet. The notes in orange cells are the developer's concerns for you to accept or reject; they are not educational judgements.
A6: What your decisions change
A7: Approved questions can be switched from 'provisional' to 'validated' (a one-line change per question, recorded with your initials and date). Until then, answers to them never change a learner's levels and never support a mastery claim. Nothing is marked approved without a named reviewer and date in this workbook.
A9: How to fill it in
A10: 1. Work through the sheets left to right. Only the yellow cells are for you.
A11: 2. Reviewer decision: choose Approve, Approve with changes, Reject or Needs discussion from the list.
A12: 3. Required change: if you want different wording, write the exact new wording. If you reject, say why in a few words.
A13: 4. Add your initials and the date on every row you decide. The 'Summary' sheet counts what is still undecided.
A14: 5. The 'Overgeneralisation' sheet lists statements we think are too broad. Please decide each one; lessons and hints cannot be approved while a flag on them is open.
A16: Example row (format only; not a real decision)
A17: (example) spl.infl.18 | B17: Approve with changes | C17: Change 'Dad is ___ the onions.' to 'Dad is ___ the carrots.' (onions is fine; carrots is more familiar to younger pupils) | D17: AB | E17: 2026-10-20
A19: Legend
A20: Yellow: for the reviewer to fill in
A21: Orange: a concern raised by the developer, for you to accept or reject
A22: Grey: example of the expected format only
A24: Scope: one rule (doubling the final consonant before -ing, -ed, -er, -est), for learners aged about 7–11 using the app with an adult.
A25: Out of scope here: the rest of the 780-question bank, the other seven inflection rules, and the scoring model.
A26: Source of everything quoted: content/english/web/doubling-journey.json, content/english/spelling/generated-items.json, and the app's screen code (file named on each row of 'Parent wording').

Sheet Summary
A1: Sheet | B1: Rows to review | C1: Decided | D1: Approved (incl. with changes) | E1: Rejected | F1: Still undecided
A2: Questions | B2: 10 | C2: =COUNTA(Questions!$N$2:$N$11) -> 0 | D2: =COUNTIF(Questions!$N$2:$N$11,"Approve")+COUNTIF(Questions!$N$2:$N$11,"Approve with changes") -> 0 | E2: =COUNTIF(Questions!$N$2:$N$11,"Reject") -> 0 | F2: =B2-C2 -> 10
A3: Lessons | B3: 3 | C3: =COUNTA(Lessons!$K$2:$K$4) -> 0 | D3: =COUNTIF(Lessons!$K$2:$K$4,"Approve")+COUNTIF(Lessons!$K$2:$K$4,"Approve with changes") -> 0 | E3: =COUNTIF(Lessons!$K$2:$K$4,"Reject") -> 0 | F3: =B3-C3 -> 3
A4: Hints | B4: 9 | C4: =COUNTA(Hints!$G$2:$G$10) -> 0 | D4: =COUNTIF(Hints!$G$2:$G$10,"Approve")+COUNTIF(Hints!$G$2:$G$10,"Approve with changes") -> 0 | E4: =COUNTIF(Hints!$G$2:$G$10,"Reject") -> 0 | F4: =B4-C4 -> 9
A5: Practice words | B5: 12 | C5: =COUNTA('Practice words'!$J$2:$J$13) -> 0 | D5: =COUNTIF('Practice words'!$J$2:$J$13,"Approve")+COUNTIF('Practice words'!$J$2:$J$13,"Approve with changes") -> 0 | E5: =COUNTIF('Practice words'!$J$2:$J$13,"Reject") -> 0 | F5: =B5-C5 -> 12
A6: Thresholds | B6: 15 | C6: =COUNTA(Thresholds!$F$2:$F$16) -> 0 | D6: =COUNTIF(Thresholds!$F$2:$F$16,"Keep") -> 0 | E6: =COUNTIF(Thresholds!$F$2:$F$16,"Change") -> 0 | F6: =B6-C6 -> 15
A7: Parent wording | B7: 40 | C7: =COUNTA('Parent wording'!$F$2:$F$41) -> 0 | D7: =COUNTIF('Parent wording'!$F$2:$F$41,"Approve")+COUNTIF('Parent wording'!$F$2:$F$41,"Approve with changes") -> 0 | E7: =COUNTIF('Parent wording'!$F$2:$F$41,"Reject") -> 0 | F7: =B7-C7 -> 40
A8: Overgeneralisation | B8: 8 | C8: =COUNTA(Overgeneralisation!$F$2:$F$9) -> 0 | D8: =COUNTIF(Overgeneralisation!$F$2:$F$9,"Approve")+COUNTIF(Overgeneralisation!$F$2:$F$9,"Approve with changes") -> 0 | E8: =COUNTIF(Overgeneralisation!$F$2:$F$9,"Reject") -> 0 | F8: =B8-C8 -> 8
A9: Total | B9: =SUM(B2:B8) -> 97 | C9: =SUM(C2:C8) -> 0 | D9: =SUM(D2:D8) -> 0 | E9: =SUM(E2:E8) -> 0 | F9: =SUM(F2:F8) -> 97
A11: Questions approved and ready to switch to 'validated' | D11: =COUNTIF(Questions!$N$2:$N$11,"Approve")+COUNTIF(Questions!$N$2:$N$11,"Approve with changes") -> 0
A12: Overgeneralisation flags still open | D12: =F8 -> 8
A14: Questions marked 'Approve with changes' are switched only after the change is made and re-checked.

Sheet Questions
A1: # | B1: ID | C1: Exact prompt (as shown) | D1: Accepted answer | E1: Tagged wrong answer → error type | F1: Rule tested | G1: Application or contrast | H1: Where the journey uses it | I1: Developer note | J1: Ambiguity risks (please check) | K1: Validation status now | L1: Counts towards levels now? | M1: Age / vocabulary suitable? (Y/N + note) | N1: Reviewer decision | O1: Required change (exact new wording if any) | P1: Reviewer initials | Q1: Date reviewed
A2: 1 | B2: spl.infl.j02 | C2: Write the -ing form of swim: She is ___ in the lake. | D2: swimming | E2: swiming → no doubling | F2: Double the final consonant of a one-syllable word ending in one vowel letter + one consonant letter, before a vowel suffix | G2: Application (must double) | H2: Diagnostic check, reassessment after teaching, or the delayed check (whichever comes first, unseen only) | I2: Copy of bank item spl.infl.02 for the journey. 'swim' is very familiar; easy start. | J2: Regional: none. A child may write 'swiming' (no doubling) or 'swimmming' (over-doubling, not tagged). | K2: provisional (review: candidate-unvalidated) | L2: No: answers are recorded but never change levels or support a mastery claim
A3: 2 | B3: spl.infl.18 | C3: Write the -ing form of chop: Dad is ___ the onions. | D3: chopping | E3: choping → no doubling | F3: Double the final consonant of a one-syllable word ending in one vowel letter + one consonant letter, before a vowel suffix | G3: Application (must double) | H3: Diagnostic check, reassessment after teaching, or the delayed check (whichever comes first, unseen only) | I3: Common verb; cooking context. | J3: None expected. 'cutting' is not accepted because the root word is given. | K3: provisional (review: candidate-unvalidated) | L3: No: answers are recorded but never change levels or support a mastery claim
A4: 3 | B4: spl.infl.24 | C4: Write the -ing form of jump: The frog is ___ into the pond. | D4: jumping | E4: jumpping → over doubling | F4: Do not double when the word ends in two consonants or has two vowel letters before the last consonant | G4: Contrast (must not double) | H4: Diagnostic check only (contrast questions are not used after teaching) | I4: Contrast: two final consonants (mp), so no doubling. | J4: Tests only clusters. It does not test w/x/y endings, unstressed syllables or vowel teams after teaching (see Overgeneralisation). | K4: provisional (review: candidate-unvalidated) | L4: No: answers are recorded but never change levels or support a mastery claim
A5: 4 | B5: spl.infl.19 | C5: Write the past tense of stop: The bus ___ outside the school. | D5: stopped | E5: stoped → no doubling | F5: Double the final consonant of a one-syllable word ending in one vowel letter + one consonant letter, before a vowel suffix | G5: Application (must double) | H5: Diagnostic check, reassessment after teaching, or the delayed check (whichever comes first, unseen only) | I5: Past tense -ed, not only -ing. | J5: Some children write 'stopt' (phonetic) or 'stops' (wrong tense); both marked wrong, neither tagged as a doubling error. | K5: provisional (review: candidate-unvalidated) | L5: No: answers are recorded but never change levels or support a mastery claim
A6: 5 | B6: spl.infl.22 | C6: Write the -ing form of trim: Grandpa is ___ the hedge. | D6: trimming | E6: triming → no doubling | F6: Double the final consonant of a one-syllable word ending in one vowel letter + one consonant letter, before a vowel suffix | G6: Application (must double) | H6: Diagnostic check, reassessment after teaching, or the delayed check (whichever comes first, unseen only) | I6: Less familiar verb. | J6: 'trim' may be unfamiliar to younger pupils; vocabulary, not spelling, could cause errors. | K6: provisional (review: candidate-unvalidated) | L6: No: answers are recorded but never change levels or support a mastery claim
A7: 6 | B7: spl.infl.21 | C7: One word in this sentence is wrong. Type the correct word: "The dog was diging in the garden." | D7: digging | E7: diging → no doubling | F7: Double the final consonant of a one-syllable word ending in one vowel letter + one consonant letter, before a vowel suffix | G7: Application (must double) | H7: Diagnostic check, reassessment after teaching, or the delayed check (whichever comes first, unseen only) | I7: Correction format: the child must find the wrong word and retype it. | J7: A child may retype the whole sentence; the app expects one word. Check the instruction is clear for the age group. | K7: provisional (review: candidate-unvalidated) | L7: No: answers are recorded but never change levels or support a mastery claim
A8: 7 | B8: spl.infl.20 | C8: Add -er to big: An elephant is ___ than a horse. | D8: bigger | E8: biger → no doubling | F8: Double the final consonant of a one-syllable word ending in one vowel letter + one consonant letter, before a vowel suffix | G8: Application (must double) | H8: Diagnostic check, reassessment after teaching, or the delayed check (whichever comes first, unseen only) | I8: Comparative -er. | J8: None expected. | K8: provisional (review: candidate-unvalidated) | L8: No: answers are recorded but never change levels or support a mastery claim
A9: 8 | B9: spl.infl.j11 | C9: Write the -ing form of run: Look, the dog is ___ after the ball. | D9: running | E9: runing → no doubling | F9: Double the final consonant of a one-syllable word ending in one vowel letter + one consonant letter, before a vowel suffix | G9: Application (must double) | H9: Diagnostic check, reassessment after teaching, or the delayed check (whichever comes first, unseen only) | I9: Copy of bank item spl.infl.11 for the journey. | J9: None expected. | K9: provisional (review: candidate-unvalidated) | L9: No: answers are recorded but never change levels or support a mastery claim
A10: 9 | B10: spl.infl.23 | C10: Add -est to wet: Today was the ___ day of the monsoon. | D10: wettest | E10: wetest → no doubling | F10: Double the final consonant of a one-syllable word ending in one vowel letter + one consonant letter, before a vowel suffix | G10: Application (must double) | H10: Diagnostic check, reassessment after teaching, or the delayed check (whichever comes first, unseen only) | I10: Superlative -est; monsoon context. | J10: Context suits learners in South Asia; check it suits your pupils. 'wetest' is the tagged error. | K10: provisional (review: candidate-unvalidated) | L10: No: answers are recorded but never change levels or support a mastery claim
A11: 10 | B11: spl.infl.25 | C11: One word in this sentence is wrong. Type the correct word: "It rainned all afternoon." | D11: rained | E11: rainned → over doubling | F11: Do not double when the word ends in two consonants or has two vowel letters before the last consonant | G11: Contrast (must not double) | H11: Diagnostic check only (contrast questions are not used after teaching) | I11: Contrast: vowel team (ai), so no doubling. Correction format. | J11: As 21: format may confuse. The only contrast with a vowel team. | K11: provisional (review: candidate-unvalidated) | L11: No: answers are recorded but never change levels or support a mastery claim

Sheet Lessons
A1: Strategy ID | B1: Name | C1: Lesson title | D1: Learning objective (developer's draft) | E1: Steps (exact) | F1: Examples (exact) | G1: Tip (exact) | H1: What the explanation claims | I1: Possible misconception it could create | J1: Independent follow-up check | K1: Reviewer decision | L1: Required change (exact new wording if any) | M1: Reviewer initials | N1: Date reviewed
A2: worked_examples | B2: Rule and worked examples | C2: Doubling the last letter | D2: Recognise when a one-syllable word needs its last consonant doubled before -ing, -ed, -er or -est, and when it does not. | E2: 1. Look at the end of the word. 2. One vowel, then one consonant? Double the consonant before -ing, -ed, -er or -est. 3. Two consonants at the end, or two vowels before the last letter? Just add the ending. | F2: stop → stopped (one vowel (o), one consonant (p): double) swim → swimming (one vowel (i), one consonant (m): double) jump → jumping (two consonants (mp): no change) | G2: hopping comes from hop; hoping comes from hope. | H2: States a letter-pattern rule (one vowel + one consonant → double) with two doubling examples and one cluster contrast. | I2: Learner may apply the rule to any word ending vowel + consonant, including fix → 'fixxing', snow → 'snowwing', visit → 'visitted', open → 'openning', and to consonant suffixes (sad → 'saddly'). | J2: The app's check: 2 unseen 'must double' questions on the learner's own, no hints. No contrast question is asked after teaching, so a learner who now doubles everything would still pass.
A3: sound_first | B3: Listen for the short vowel | C3: Listen to the vowel | D3: Use the short vowel sound in a one-syllable word to decide whether to double the last consonant. | E3: 1. Say the word out loud. 2. Do you hear a short vowel, as in cat, sit, hop or cup? 3. A short vowel before one consonant needs a double letter to stay short: tap → tapping. | F3: hop → hopping (short o: double p) hope → hoping (long o: no double) tap → tapping, tape → taping (short a doubles; long a does not) | G3: The double letter is a guard that keeps the vowel short. | H3: Links doubling to vowel length (short vowel: double; long vowel / split digraph: no double), contrasting hop/hope and tap/tape. | I3: Learner may double after any short vowel sound: head → 'headding', visit → 'visitting', panic → 'panicing/panicc', fix → 'fixxing'. Vowel length also varies by accent. | J3: The app's check: 2 unseen 'must double' questions on the learner's own, no hints. No contrast question is asked after teaching, so a learner who now doubles everything would still pass.
A4: word_building | B4: Build the word in parts | C4: Build the word in three parts | D4: Build the inflected word from root + optional extra consonant + ending, deciding first whether the extra letter is needed. | E4: 1. Part 1: the root word (hop). 2. Part 2: an extra copy of the last letter, only if the root ends in one vowel + one consonant (p). 3. Part 3: the ending (-ing). Put them together: hop + p + ing = hopping. | F4: chop + p + ing = chopping (o then p: add a p) rain + ed = rained (two vowels (ai): nothing extra) jump + ing = jumping (two consonants (mp): nothing extra) | G4: Sort first: does it need the extra letter or not? | H4: Morphological: root | doubled letter (if one vowel + one consonant) | suffix, with a vowel-team and a cluster contrast. | I4: Same pattern rule as worked_examples, so the same overgeneralisation (w/x/y, unstressed final syllables, consonant suffixes). | J4: The app's check: 2 unseen 'must double' questions on the learner's own, no hints. No contrast question is asked after teaching, so a learner who now doubles everything would still pass.

Sheet Hints
A1: Strategy | B1: Level | C1: Template (exact) | D1: As shown for clap + -ing | E1: As shown for skip + -ed | F1: Developer concern | G1: Reviewer decision | H1: Required change (exact new wording if any) | I1: Reviewer initials | J1: Date reviewed
A2: worked_examples | B2: 1 | C2: Look at the end of the word: one vowel, then one consonant? | D2: Look at the end of the word: one vowel, then one consonant? | E2: Look at the end of the word: one vowel, then one consonant?
A3: worked_examples | B3: 2 | C3: {base} ends in one vowel and one consonant ({last}). What happens to the {last}? | D3: clap ends in one vowel and one consonant (p). What happens to the p? | E3: skip ends in one vowel and one consonant (p). What happens to the p?
A4: worked_examples | B4: 3 | C4: Double it: {base} + {last} + {ending}. | D4: Double it: clap + p + ing. | E4: Double it: skip + p + ed. | F4: Gives the answer: the child only has to join three parts. Is level 3 meant to be a model answer?
A5: sound_first | B5: 1 | C5: Say {base} out loud. Is the vowel short, as in cat or sit? | D5: Say clap out loud. Is the vowel short, as in cat or sit? | E5: Say skip out loud. Is the vowel short, as in cat or sit? | F5: Relies on hearing vowel length, which varies by accent and is hard for some children.
A6: sound_first | B6: 2 | C6: The short vowel needs a guard: the {last} doubles. | D6: The short vowel needs a guard: the p doubles. | E6: The short vowel needs a guard: the p doubles. | F6: States as a fact that a short vowel 'needs a guard'. True for these one-syllable words; overgeneralises beyond them.
A7: sound_first | B7: 3 | C7: {base} + {last} + {ending}. | D7: clap + p + ing. | E7: skip + p + ed. | F7: Gives the answer.
A8: word_building | B8: 1 | C8: Split it: {base} | ? | {ending}. Does {base} end in one vowel and one consonant? | D8: Split it: clap | ? | ing. Does clap end in one vowel and one consonant? | E8: Split it: skip | ? | ed. Does skip end in one vowel and one consonant?
A9: word_building | B9: 2 | C9: Yes, so the middle part is another {last}. | D9: Yes, so the middle part is another p. | E9: Yes, so the middle part is another p.
A10: word_building | B10: 3 | C10: {base} + {last} + {ending}. | D10: clap + p + ing. | E10: skip + p + ed. | F10: Gives the answer.

Sheet Practice words
A1: # | B1: ID | C1: Root | D1: Ending | E1: Prompt (exact) | F1: Answer | G1: Tagged wrong answer | H1: Explanation stored with the item (not shown in the journey) | I1: Developer concern | J1: Reviewer decision | K1: Required change (exact new wording if any) | L1: Reviewer initials | M1: Date reviewed
A2: 1 | B2: gen.infl.add_ending.clapping | C2: clap | D2: -ing | E2: Add -ing to "clap" and write the new word. | F2: clapping | G2: claping → no doubling | H2: clap has one syllable, one short vowel and one final consonant, so the last letter doubles before -ing: clapping.
A3: 2 | B3: gen.infl.add_ending.cutting | C3: cut | D3: -ing | E3: Add -ing to "cut" and write the new word. | F3: cutting | G3: cuting → no doubling | H3: cut has one syllable, one short vowel and one final consonant, so the last letter doubles before -ing: cutting.
A4: 3 | B4: gen.infl.add_ending.dipped | C4: dip | D4: -ed | E4: Add -ed to "dip" and write the new word. | F4: dipped | G4: diped → no doubling | H4: dip has one syllable, one short vowel and one final consonant, so the last letter doubles before -ed: dipped.
A5: 4 | B5: gen.infl.add_ending.fitting | C5: fit | D5: -ing | E5: Add -ing to "fit" and write the new word. | F5: fitting | G5: fiting → no doubling | H5: fit has one syllable, one short vowel and one final consonant, so the last letter doubles before -ing: fitting.
A6: 5 | B6: gen.infl.add_ending.jogging | C6: jog | D6: -ing | E6: Add -ing to "jog" and write the new word. | F6: jogging | G6: joging → no doubling | H6: jog has one syllable, one short vowel and one final consonant, so the last letter doubles before -ing: jogging.
A7: 6 | B7: gen.infl.add_ending.mapping | C7: map | D7: -ing | E7: Add -ing to "map" and write the new word. | F7: mapping | G7: maping → no doubling | H7: map has one syllable, one short vowel and one final consonant, so the last letter doubles before -ing: mapping.
A8: 7 | B8: gen.infl.add_ending.shopping | C8: shop | D8: -ing | E8: Add -ing to "shop" and write the new word. | F8: shopping | G8: shoping → no doubling | H8: shop has one syllable, one short vowel and one final consonant, so the last letter doubles before -ing: shopping.
A9: 8 | B9: gen.infl.add_ending.sitting | C9: sit | D9: -ing | E9: Add -ing to "sit" and write the new word. | F9: sitting | H9: sit has one syllable, one short vowel and one final consonant, so the last letter doubles before -ing: sitting. | I9: No tagged wrong answer: the undoubled form is a real word (site + ing), so a wrong answer is not labelled as a doubling error.
A10: 9 | B10: gen.infl.add_ending.skipped | C10: skip | D10: -ed | E10: Add -ed to "skip" and write the new word. | F10: skipped | G10: skiped → no doubling | H10: skip has one syllable, one short vowel and one final consonant, so the last letter doubles before -ed: skipped.
A11: 10 | B11: gen.infl.add_ending.spinning | C11: spin | D11: -ing | E11: Add -ing to "spin" and write the new word. | F11: spinning | G11: spining → no doubling | H11: spin has one syllable, one short vowel and one final consonant, so the last letter doubles before -ing: spinning.
A12: 11 | B12: gen.infl.add_ending.winning | C12: win | D12: -ing | E12: Add -ing to "win" and write the new word. | F12: winning | H12: win has one syllable, one short vowel and one final consonant, so the last letter doubles before -ing: winning. | I12: No tagged wrong answer: the undoubled form is a real word (wine + ing), so a wrong answer is not labelled as a doubling error.
A13: 12 | B13: gen.infl.add_ending.zipping | C13: zip | D13: -ing | E13: Add -ing to "zip" and write the new word. | F13: zipping | G13: ziping → no doubling | H13: zip has one syllable, one short vowel and one final consonant, so the last letter doubles before -ing: zipping.
B15: Concern for the whole set
B16: All 12 practice words double. Guided practice never shows a word that must not double, so practice may reinforce 'always double'. Please say whether contrast words should be added before testing with children.

Sheet Thresholds
A1: Policy | B1: Setting | C1: Draft value | D1: What it means for a child | E1: Suggested value (if different) | F1: Reviewer decision | G1: Required change (exact new wording if any) | H1: Reviewer initials | I1: Date reviewed
A2: planner-policy@0-draft | B2: diagnosticMax | C2: 5 | D2: At most 5 questions on their own before teaching (fewer once the same error is seen twice or the rule looks weak).
A3: planner-policy@0-draft | B3: guidedItems | C3: 4 | D3: 4 practice words with help in each teaching block.
A4: planner-policy@0-draft | B4: hintLevels | C4: 3 | D4: Up to 3 hints per practice word.
A5: planner-policy@0-draft | B5: reassessItems | C5: 2 | D5: 2 unseen words on their own after each lesson.
A6: planner-policy@0-draft | B6: reassessPassMin | C6: 2 | D6: Both must be right for the lesson to count as having worked.
A7: planner-policy@0-draft | B7: maxStrategiesBeforeHuman | C7: 3 | D7: After 3 different lessons have not worked, stop and recommend a teacher or parent.
A8: planner-policy@0-draft | B8: retentionGapDays | C8: 7 | D8: The delayed check is offered from 7 days after the last answer.
A9: planner-policy@0-draft | B9: retentionItems | C9: 2 | D9: 2 unseen words in the delayed check.
A10: rule-evidence-policy@0-draft | B10: demonstratedMinApplications | C10: 4 | D10: 'Shown on new words' needs at least 4 'must double' answers on their own (smallest passing records: 4/4, 5/5, 5/6, 6/7, 7/8).
A11: rule-evidence-policy@0-draft | B11: demonstratedMinContrastCorrect | C11: 1 | D11: ...and at least 1 'must not double' answer right.
A12: rule-evidence-policy@0-draft | B12: window | C12: 8 | D12: Only the most recent 8 answers are considered.
A13: rule-evidence-policy@0-draft | B13: weakRate / weakProbability | C13: 0.5 / 0.8 | D13: 'Not yet' when it is at least 80% likely that fewer than half would be right.
A14: rule-evidence-policy@0-draft | B14: activeMinErrors | C14: 2 | D14: The same error type on 2 different words, on their own, is reported as a pattern.
A15: rule-evidence-policy@0-draft | B15: delayedGapDays / delayedMinApplications | C15: 7 / 2 | D15: The delayed check needs 2 answers at least 7 days after the previous evidence, with no practice earlier in that session.
A16: app | B16: JOURNEY_IDLE_MS | C16: 6 hours | D16: A journey left open for 6 hours is closed when next opened.
A18: These values are drafts. This review records opinions on them; changing any of them is a separate decision and is not part of this pilot preparation.

Sheet Parent wording
A1: Reader | B1: Where | C1: Exact text ({…} = filled in by the app) | D1: Source file | E1: Developer concern | F1: Reviewer decision | G1: Required change (exact new wording if any) | H1: Reviewer initials | I1: Date reviewed
A2: Child | B2: Today card | C2: hop → hopping, stop → stopped. A few questions on your own, then teaching that changes if it is not working, then new words on your own. | D2: frontend/src/english/ui/App.tsx
A3: Child | B3: Today card | C3: Demonstration content: the questions, lessons and hints are provisional and not yet reviewed by an educator. They do not change your levels. | D3: frontend/src/english/ui/App.tsx
A4: Child | B4: Question label | C4: On your own: no hints | D4: frontend/src/english/ui/Journey.tsx
A5: Child | B5: Question label | C5: New word, on your own: no hints | D5: frontend/src/english/ui/Journey.tsx
A6: Child | B6: Question label | C6: A week later: has it stuck? No hints | D6: frontend/src/english/ui/Journey.tsx | E6: Shown at 7 or 30 days alike.
A7: Child | B7: Lesson heading | C7: Let's try a different way | D7: frontend/src/english/ui/Journey.tsx
A8: Child | B8: Lesson: why this | C8: Not yet right on new words: teaching the rule. | D8: packages/english-core/src/planner.ts | E8: Also shown when the child made no rule error but the 5-question check ended before enough answers (see Pilot readiness, finding P-1).
A9: Child | B9: Lesson: why this | C9: The same mistake appeared on different words: teaching the rule. | D9: packages/english-core/src/planner.ts
A10: Child | B10: Lesson: why this | C10: Shown before, but not remembered after a delay. A short refresher with the approach that helped before. | D10: packages/english-core/src/planner.ts
A11: Child | B11: Practice label | C11: Practice with help: this does not count as doing it on your own | D11: frontend/src/english/ui/Journey.tsx
A12: Child | B12: Feedback | C12: Not yet. A hint might help. | D12: frontend/src/english/ui/Journey.tsx
A13: Child | B13: Summary | C13: You doubled the letter correctly on new words, on your own. We'll check again in about a week to see if it has stuck. | D13: frontend/src/english/ui/Journey.tsx
A14: Child | B14: Summary | C14: After the lesson you got new words right on your own. That's real progress. A few more, and a check in a week, will show it is secure. | D14: frontend/src/english/ui/Journey.tsx
A15: Child | B15: Summary | C15: This one is tricky, and that's fine. We've tried three different ways; next, it's best to work on it with a grown-up. You can carry on with other practice. | D15: frontend/src/english/ui/Journey.tsx | E15: Check tone: encouraging, not discouraging?
A16: Child | B16: Summary | C16: A week later, you still remembered it. Well done. | D16: frontend/src/english/ui/Journey.tsx
A17: Parent | B17: Skill | C17: Doubling the last consonant before an ending (hop → hopping, stop → stopped, big → bigger) | D17: frontend/src/english/logic/journey.ts | E17: 'before an ending' is too broad: only endings that start with a vowel (sad → sadly does not double).
A18: Parent | B18: Where things stand | C18: Not enough answers yet to say. | D18: frontend/src/english/logic/journey.ts
A19: Parent | B19: Where things stand | C19: Mixed results so far: right and wrong in different ways. | D19: frontend/src/english/logic/journey.ts
A20: Parent | B20: Where things stand | C20: Not yet doing this without help. | D20: frontend/src/english/logic/journey.ts
A21: Parent | B21: Where things stand | C21: Getting there: some right on new words without help, not yet consistently. | D21: frontend/src/english/logic/journey.ts
A22: Parent | B22: Where things stand | C22: Shown without help on new words today. Not yet checked after a delay. | D22: frontend/src/english/logic/journey.ts
A23: Parent | B23: Where things stand | C23: Shown without help, and still right after at least a week. | D23: frontend/src/english/logic/journey.ts | E23: Always followed by the provisional note below while content is provisional.
A24: Parent | B24: Where things stand | C24: (on provisional questions: a demonstration, not a verified result) | D24: frontend/src/english/logic/journey.ts
A25: Parent | B25: Where things stand | C25: Right with help in practice, not yet without help. | D25: frontend/src/english/logic/journey.ts
A26: Parent | B26: Where things stand | C26: Right on new words without help after teaching. Progress, not yet mastery: more answers and a check after a week are needed. | D26: frontend/src/english/logic/journey.ts
A27: Parent | B27: Where things stand | C27: First shown on {date}; not remembered at the check after a week. Needs refreshing. | D27: frontend/src/english/logic/journey.ts
A28: Parent | B28: Difficulty: pattern | C28: Pattern in answers given without help: {error} ({n} times, on different words). | D28: frontend/src/english/logic/journey.ts
A29: Parent | B29: Difficulty: on their own | C29: Wrote "{typed}" for "{answer}", on their own (no hint, first try). | D29: frontend/src/english/logic/journey.ts | E29: Also used for answers at the delayed check; it does not say which answers were at the check.
A30: Parent | B30: Difficulty: slip | C30: Wrote "{typed}" for "{answer}": letters swapped, the rule itself was applied. | D30: frontend/src/english/logic/journey.ts
A31: Parent | B31: Difficulty: with help | C31: With help (practice): wrote "{typed}" for "{answer}", then {right after N hints | right at a later try | not right, even with help}. | D31: frontend/src/english/logic/journey.ts
A32: Parent | B32: Difficulty: unknown | C32: Wrote "{typed}" for "{answer}" (recorded before help was tracked: whether help was given is unknown). | D32: frontend/src/english/logic/journey.ts
A33: Parent | B33: Help received | C33: {n} lesson(s) ({names}). Practice with help: {a} right at the first try, {b} right after a hint or second try, {h} hints used. | D33: frontend/src/english/ui/Journey.tsx
A34: Parent | B34: Help received | C34: None: every answer so far was given without help. | D34: frontend/src/english/ui/Journey.tsx
A35: Parent | B35: After teaching | C35: After "{strategy}": {right} of {total} new words right without help. | D35: frontend/src/english/ui/Journey.tsx
A36: Parent | B36: Remembered later | C36: Not yet: it first needs to be shown securely on its own, then checked again after a week. | D36: frontend/src/english/ui/Journey.tsx
A37: Parent | B37: Remembered later | C37: Pending: not yet checked after a delay. | D37: frontend/src/english/ui/Journey.tsx
A38: Parent | B38: Remembered later | C38: Confirmed: still right after at least a week. | D38: frontend/src/english/ui/Journey.tsx
A39: Parent | B39: Remembered later | C39: Not kept: wrong at the check after a week. Earlier progress is still recorded. | D39: frontend/src/english/ui/Journey.tsx
A40: Parent | B40: Recommended | C40: {n} different approaches have not yet worked. We recommend a teacher or parent works on this with them; the app has paused this rule rather than repeating it. | D40: frontend/src/english/logic/journey.ts
...

Sheet Overgeneralisation
A1: Flag | B1: Where it appears | C1: Statement (exact or abridged) | D1: Why it is too broad (counterexamples) | E1: Possible fix (developer suggestion, not applied) | F1: Reviewer decision | G1: Required change (exact new wording if any) | H1: Reviewer initials | I1: Date reviewed
A2: OG-1 | B2: Lessons: worked_examples step 2; word_building step 2; hints worked_examples 1–2, word_building 1 | C2: One vowel, then one consonant? Double the consonant before -ing, -ed, -er or -est. | D2: Words ending in w, x or y never double: fix → fixing, snow → snowing, play → playing. | E2: Add: 'Never double w, x or y.'
A3: OG-2 | B3: Same as OG-1 | C3: One vowel, then one consonant? Double… | D3: In longer words doubling depends on stress: begin → beginning, forget → forgetting, but visit → visited, open → opening, garden → gardening. (UK travel → travelled, US traveled.) | E3: Limit the rule explicitly to one-syllable words: 'In a short word with one syllable…'; teach longer words separately later.
A4: OG-3 | B4: Lesson sound_first step 3, tip; hint sound_first 2 | C4: A short vowel before one consonant needs a double letter to stay short. | D4: A short vowel sound is not enough on its own: head → heading, bread, visit → visiting, panic → panicking (c → ck), fix → fixing (x is two sounds). Vowel length also varies by accent. | E4: Present the short vowel as a reason the pattern exists, not as the test: keep the letter test (one vowel letter + one consonant letter, one syllable) as the rule.
A5: OG-4 | B5: Lesson worked_examples step 3 | C5: Two consonants at the end, or two vowels before the last letter? Just add the ending. | D5: 'qu' counts as a consonant sound: quit → quitting, quiz → quizzes, squat → squatting double although two vowel letters come before the last letter. | E5: Accept as a known exception not taught at this level, or add a note for teachers only.
A6: OG-5 | B6: Parent skill line; lesson steps list the endings but the skill line does not | C6: Doubling the last consonant before an ending | D6: Only endings that start with a vowel: sad → sadly, ship → shipment, wet → wetness do not double. | E6: '…before an ending that starts with a vowel (-ing, -ed, -er, -est)'.
A7: OG-6 | B7: Hints, level 3 (all three strategies) | C7: Double it: {base} + {last} + {ending}. | D7: Not an overgeneralisation but a validity risk: the hint gives the answer, so 'right after 3 hints' shows little. | E7: Keep as a model answer and treat as 'shown the answer' in the parent report, or remove level 3.
A8: OG-7 | B8: Journey design: practice words and the check after teaching | C8: All 12 practice words double; the 2 questions after teaching always double. | D8: A child who learns 'always double' passes the check after teaching. Over-doubling would only show at the next diagnostic question. | E8: Add at least one 'must not double' word to practice and to the check after teaching (content change, needs approval).
A9: OG-8 | B9: Question rationale texts (internal, not shown to children): spl.infl.18 'One short vowel, one final consonant: double before -ing.' | C9: One short vowel, one final consonant: double… | D9: Same as OG-1 to OG-3; internal only. | E9: Align with whatever wording is approved for the lessons.
